Workbook

Sheet Assumptions
A1: SPY Aug. 28, 2026 $750 Put Scenario Model
A3: Input | B3: Value | C3: Units | D3: Notes / Source
A4: Baseline SPY price | B4: 773.73 | C4: $/share | D4: From the Robinhood Legend screenshot supplied in chat on Aug. 10, 2026.
A5: Put strike | B5: 750 | C5: $/share | D5: Selected contract: SPY Aug. 28, 2026 $750 put.
A6: Entry premium | B6: 2.1 | C6: $/share | D6: Your proposed limit entry; total premium is premium x 100.
A7: Contract multiplier | B7: 100 | C7: shares/contract | D7: Standard U.S. equity/ETF option multiplier.
A8: Implied volatility | B8: 0.1501 | C8: % | D8: Approx. constant IV calibrated near the observed ~$2.15 option mark with 18 DTE.
A9: Risk-free rate | B9: 0.0379 | C9: % | D9: Approx. short-term Treasury rate used for scenario pricing.
A10: Expiration date | B10: 46262 | C10: date | D10: Contract expiration.
A11: Starting DTE | B11: 18 | C11: calendar days | D11: Days to expiration from Aug. 10, 2026.
A13: Excel compatibility | B13: Uses legacy NORMSDIST() in pricing formulas to avoid #NAME? errors in Excel.
A14: Model methodology
A15: Option-price cells use a Black-Scholes European put approximation with constant IV and rate. SPY options are American-style, so real market prices can differ. The model is intended as a scenario guide, not a fill-price forecast.
A18: Key outputs
A19: Total premium at risk | B19: =B6*B7
A20: Expiration breakeven | B20: =B5-B6
A21: Breakeven decline from baseline | B21: =1-(B20/B4)

Sheet Option Price Matrix
A1: Option Price Matrix
A2: Rows = SPY decline from baseline. Columns = calendar days remaining until Aug. 28 expiration.
A3: SPY Drop | B3: SPY Price | C3: 18D | D3: 17D | E3: 16D | F3: 15D | G3: 14D | H3: 13D | I3: 12D | J3: 11D | K3: 10D | L3: 9D | M3: 8D | N3: 7D | O3: 6D | P3: 5D | Q3: 4D | R3: 3D | S3: 2D | T3: 1D | U3: 0D
A4: 0.01 | B4: ='Assumptions'!$B$4*(1-A4) | C4: =IF(C$24=0,MAX('Assumptions'!$B$5-$B4,0),'Assumptions'!$B$5*EXP(-'Assumptions'!$B$9*(C$24/365))*NORMSDIST(-(((LN($B4/'Assumptions'!$B$5)+('Assumptions'!$B$9+0.5*'Assumptions'!$B$8^2)*(C$24/365))/('Assumptions'!$B$8*SQRT((C$24/365))))-'Assumptions'!$B$8*SQRT((C$24/365))))-$B4*NORMSDIST(-((LN($B4/'Assumptions'!$B$5)+('Assumptions'!$B$9+0.5*'Assumptions'!$B$8^2)*(C$24/365))/('Assumptions'!$B$8*SQRT((C$24/365)))))) | D4: =IF(D$24=0,MAX('Assumptions'!$B$5-$B4,0),'Assumptions'!$B$5*EXP(-'Assumptions'!$B$9*(D$24/365))*NORMSDIST(-(((LN($B4/'Assumptions'!$B$5)+('Assumptions'!$B$9+0.5*'Assumptions'!$B$8^2)*(D$24/365))/('Assumptions'!$B$8*SQRT((D$24/365))))-'Assumptions'!$B$8*SQRT((D$24/365))))-$B4*NORMSDIST(-((LN($B4/'Assumptions'!$B$5)+('Assumptions'!$B$9+0.5*'Assumptions'!$B$8^2)*(D$24/365))/('Assumptions'!$B$8*SQRT((D$24/365)))))) | E4: =IF(E$24=0,MAX('Assumptions'!$B$5-$B4,0),'Assumptions'!$B$5*EXP(-'Assumptions'!$B$9*(E$24/365))*NORMSDIST(-(((LN($B4/'Assumptions'!$B$5)+('Assumptions'!$B$9+0.5*'Assumptions'!$B$8^2)*(E$24/365))/('Assumptions'!$B$8*SQRT((E$24/365))))-'Assumptions'!$B$8*SQRT((E$24/365))))-$B4*NORMSDIST(-((LN($B4/'Assumptions'!$B$5)+('Assumptions'!$B$9+0.5*'Assumptions'!$B$8^2)*(E$24/365))/('Assumptions'!$B$8*SQRT((E$24/365)))))) | F4: =IF(F$24=0,MAX('Assumptions'!$B$5-$B4,0),'Assumptions'!$B$5*EXP(-'Assumptions'!$B$9*(F$24/365))*NORMSDIST(-(((LN($B4/'Assumptions'!$B$5)+('Assumptions'!$B$9+0.5*'Assumptions'!$B$8^2)*(F$24/365))/('Assumptions'!$B$8*SQRT((F$24/365))))-'Assumptions'!$B$8*SQRT((F$24/365))))-$B4*NORMSDIST(-((LN($B4/'Assumptions'!$B$5)+('Assumptions'!$B$9+0.5*'Assumptions'!$B$8^2)*(F$24/365))/('Assumptions'!$B$8*SQRT((F$24/365)))))) | G4: =IF(G$24=0,MAX('Assumptions'!$B$5-$B4,0),'Assumptions'!$B$5*EXP(-'Assumptions'!$B$9*(G$24/365))*NORMSDIST(-(((LN($B4/'Assumptions'!$B$5)+('Assumptions'!$B$9+0.5*'Assumptions'!$B$8^2)*(G$24/365))/('Assumptions'!$B$8*SQRT((G$24/365))))-'Assumptions'!$B$8*SQRT((G$24/365))))-$B4*NORMSDIST(-((LN($B4/'Assumptions'!$B$5)+('Assumptions'!$B$9+0.5*'Assumptions'!$B$8^2)*(G$24/365))/('Assumptions'!$B$8*SQRT((G$24/365)))))) | H4: =IF(H$24=0,MAX('Assumptions'!$B$5-$B4,0),'Assumptions'!$B$5*EXP(-'Assumptions'!$B$9*(H$24/365))*NORMSDIST(-(((LN($B4/'Assumptions'!$B$5)+('Assumptions'!$B$9+0.5*'Assumptions'!$B$8^2)*(H$24/365))/('Assumptions'!$B$8*SQRT((H$24/365))))-'Assumptions'!$B$8*SQRT((H$24/365))))-$B4*NORMSDIST(-((LN($B4/'Assumptions'!$B$5)+('Assumptions'!$B$9+0.5*'Assumptions'!$B$8^2)*(H$24/365))/('Assumptions'!$B$8*SQRT((H$24/365)))))) | I4: =IF(I$24=0,MAX('Assumptions'!$B$5-$B4,0),'Assumptions'!$B$5*EXP(-'Assumptions'!$B$9*(I$24/365))*NORMSDIST(-(((LN($B4/'Assumptions'!$B$5)+('Assumptions'!$B$9+0.5*'Assumptions'!$B$8^2)*(I$24/365))/('Assumptions'!$B$8*SQRT((I$24/365))))-'Assumptions'!$B$8*SQRT((I$24/365))))-$B4*NORMSDIST(-((LN($B4/'Assumptions'!$B$5)+('Assumptions'!$B$9+0.5*'Assumptions'!$B$8^2)*(I$24/365))/('Assumptions'!$B$8*SQRT((I$24/365)))))) | J4: =IF(J$24=0,MAX('Assumptions'!$B$5-$B4,0),'Assumptions'!$B$5*EXP(-'Assumptions'!$B$9*(J$24/365))*NORMSDIST(-(((LN($B4/'Assumptions'!$B$5)+('Assumptions'!$B$9+0.5*'Assumptions'!$B$8^2)*(J$24/365))/('Assumptions'!$B$8*SQRT((J$24/365))))-'Assumptions'!$B$8*SQRT((J$24/365))))-$B4*NORMSDIST(-((LN($B4/'Assumptions'!$B$5)+('Assumptions'!$B$9+0.5*'Assumptions'!$B$8^2)*(J$24/365))/('Assumptions'!$B$8*SQRT((J$24/365)))))) | ... U4: =IF(U$24=0,MAX('Assumptions'!$B$5-$B4,0),'Assumptions'!$B$5*EXP(-'Assumptions'!$B$9*(U$24/365))*NORMSDIST(-(((LN($B4/'Assumptions'!$B$5)+('Assumptions'!$B$9+0.5*'Assumptions'!$B$8^2)*(U$24/365))/('Assumptions'!$B$8*SQRT((U$24/365))))-'Assumptions'!$B$8*SQRT((U$24/365))))-$B4*NORMSDIST(-((LN($B4/'Assumptions'!$B$5)+('Assumptions'!$B$9+0.5*'Assumptions'!$B$8^2)*(U$24/365))/('Assumptions'!$B$8*SQRT((U$24/365))))))
A5: 0.02 | B5: ='Assumptions'!$B$4*(1-A5) | C5: =IF(C$24=0,MAX('Assumptions'!$B$5-$B5,0),'Assumptions'!$B$5*EXP(-'Assumptions'!$B$9*(C$24/365))*NORMSDIST(-(((LN($B5/'Assumptions'!$B$5)+('Assumptions'!$B$9+0.5*'Assumptions'!$B$8^2)*(C$24/365))/('Assumptions'!$B$8*SQRT((C$24/365))))-'Assumptions'!$B$8*SQRT((C$24/365))))-$B5*NORMSDIST(-((LN($B5/'Assumptions'!$B$5)+('Assumptions'!$B$9+0.5*'Assumptions'!$B$8^2)*(C$24/365))/('Assumptions'!$B$8*SQRT((C$24/365)))))) | D5: =IF(D$24=0,MAX('Assumptions'!$B$5-$B5,0),'Assumptions'!$B$5*EXP(-'Assumptions'!$B$9*(D$24/365))*NORMSDIST(-(((LN($B5/'Assumptions'!$B$5)+('Assumptions'!$B$9+0.5*'Assumptions'!$B$8^2)*(D$24/365))/('Assumptions'!$B$8*SQRT((D$24/365))))-'Assumptions'!$B$8*SQRT((D$24/365))))-$B5*NORMSDIST(-((LN($B5/'Assumptions'!$B$5)+('Assumptions'!$B$9+0.5*'Assumptions'!$B$8^2)*(D$24/365))/('Assumptions'!$B$8*SQRT((D$24/365)))))) | E5: =IF(E$24=0,MAX('Assumptions'!$B$5-$B5,0),'Assumptions'!$B$5*EXP(-'Assumptions'!$B$9*(E$24/365))*NORMSDIST(-(((LN($B5/'Assumptions'!$B$5)+('Assumptions'!$B$9+0.5*'Assumptions'!$B$8^2)*(E$24/365))/('Assumptions'!$B$8*SQRT((E$24/365))))-'Assumptions'!$B$8*SQRT((E$24/365))))-$B5*NORMSDIST(-((LN($B5/'Assumptions'!$B$5)+('Assumptions'!$B$9+0.5*'Assumptions'!$B$8^2)*(E$24/365))/('Assumptions'!$B$8*SQRT((E$24/365)))))) | F5: =IF(F$24=0,MAX('Assumptions'!$B$5-$B5,0),'Assumptions'!$B$5*EXP(-'Assumptions'!$B$9*(F$24/365))*NORMSDIST(-(((LN($B5/'Assumptions'!$B$5)+('Assumptions'!$B$9+0.5*'Assumptions'!$B$8^2)*(F$24/365))/('Assumptions'!$B$8*SQRT((F$24/365))))-'Assumptions'!$B$8*SQRT((F$24/365))))-$B5*NORMSDIST(-((LN($B5/'Assumptions'!$B$5)+('Assumptions'!$B$9+0.5*'Assumptions'!$B$8^2)*(F$24/365))/('Assumptions'!$B$8*SQRT((F$24/365)))))) | G5: =IF(G$24=0,MAX('Assumptions'!$B$5-$B5,0),'Assumptions'!$B$5*EXP(-'Assumptions'!$B$9*(G$24/365))*NORMSDIST(-(((LN($B5/'Assumptions'!$B$5)+('Assumptions'!$B$9+0.5*'Assumptions'!$B$8^2)*(G$24/365))/('Assumptions'!$B$8*SQRT((G$24/365))))-'Assumptions'!$B$8*SQRT((G$24/365))))-$B5*NORMSDIST(-((LN($B5/'Assumptions'!$B$5)+('Assumptions'!$B$9+0.5*'Assumptions'!$B$8^2)*(G$24/365))/('Assumptions'!$B$8*SQRT((G$24/365)))))) | H5: =IF(H$24=0,MAX('Assumptions'!$B$5-$B5,0),'Assumptions'!$B$5*EXP(-'Assumptions'!$B$9*(H$24/365))*NORMSDIST(-(((LN($B5/'Assumptions'!$B$5)+('Assumptions'!$B$9+0.5*'Assumptions'!$B$8^2)*(H$24/365))/('Assumptions'!$B$8*SQRT((H$24/365))))-'Assumptions'!$B$8*SQRT((H$24/365))))-$B5*NORMSDIST(-((LN($B5/'Assumptions'!$B$5)+('Assumptions'!$B$9+0.5*'Assumptions'!$B$8^2)*(H$24/365))/('Assumptions'!$B$8*SQRT((H$24/365)))))) | I5: =IF(I$24=0,MAX('Assumptions'!$B$5-$B5,0),'Assumptions'!$B$5*EXP(-'Assumptions'!$B$9*(I$24/365))*NORMSDIST(-(((LN($B5/'Assumptions'!$B$5)+('Assumptions'!$B$9+0.5*'Assumptions'!$B$8^2)*(I$24/365))/('Assumptions'!$B$8*SQRT((I$24/365))))-'Assumptions'!$B$8*SQRT((I$24/365))))-$B5*NORMSDIST(-((LN($B5/'Assumptions'!$B$5)+('Assumptions'!$B$9+0.5*'Assumptions'!$B$8^2)*(I$24/365))/('Assumptions'!$B$8*SQRT((I$24/365)))))) | J5: =IF(J$24=0,MAX('Assumptions'!$B$5-$B5,0),'Assumptions'!$B$5*EXP(-'Assumptions'!$B$9*(J$24/365))*NORMSDIST(-(((LN($B5/'Assumptions'!$B$5)+('Assumptions'!$B$9+0.5*'Assumptions'!$B$8^2)*(J$24/365))/('Assumptions'!$B$8*SQRT((J$24/365))))-'Assumptions'!$B$8*SQRT((J$24/365))))-$B5*NORMSDIST(-((LN($B5/'Assumptions'!$B$5)+('Assumptions'!$B$9+0.5*'Assumptions'!$B$8^2)*(J$24/365))/('Assumptions'!$B$8*SQRT((J$24/365)))))) | ... U5: =IF(U$24=0,MAX('Assumptions'!$B$5-$B5,0),'Assumptions'!$B$5*EXP(-'Assumptions'!$B$9*(U$24/365))*NORMSDIST(-(((LN($B5/'Assumptions'!$B$5)+('Assumptions'!$B$9+0.5*'Assumptions'!$B$8^2)*(U$24/365))/('Assumptions'!$B$8*SQRT((U$24/365))))-'Assumptions'!$B$8*SQRT((U$24/365))))-$B5*NORMSDIST(-((LN($B5/'Assumptions'!$B$5)+('Assumptions'!$B$9+0.5*'Assumptions'!$B$8^2)*(U$24/365))/('Assumptions'!$B$8*SQRT((U$24/365))))))
A6: 0.03 | B6: ='Assumptions'!$B$4*(1-A6) | C6: =IF(C$24=0,MAX('Assumptions'!$B$5-$B6,0),'Assumptions'!$B$5*EXP(-'Assumptions'!$B$9*(C$24/365))*NORMSDIST(-(((LN($B6/'Assumptions'!$B$5)+('Assumptions'!$B$9+0.5*'Assumptions'!$B$8^2)*(C$24/365))/('Assumptions'!$B$8*SQRT((C$24/365))))-'Assumptions'!$B$8*SQRT((C$24/365))))-$B6*NORMSDIST(-((LN($B6/'Assumptions'!$B$5)+('Assumptions'!$B$9+0.5*'Assumptions'!$B$8^2)*(C$24/365))/('Assumptions'!$B$8*SQRT((C$24/365)))))) | D6: =IF(D$24=0,MAX('Assumptions'!$B$5-$B6,0),'Assumptions'!$B$5*EXP(-'Assumptions'!$B$9*(D$24/365))*NORMSDIST(-(((LN($B6/'Assumptions'!$B$5)+('Assumptions'!$B$9+0.5*'Assumptions'!$B$8^2)*(D$24/365))/('Assumptions'!$B$8*SQRT((D$24/365))))-'Assumptions'!$B$8*SQRT((D$24/365))))-$B6*NORMSDIST(-((LN($B6/'Assumptions'!$B$5)+('Assumptions'!$B$9+0.5*'Assumptions'!$B$8^2)*(D$24/365))/('Assumptions'!$B$8*SQRT((D$24/365)))))) | E6: =IF(E$24=0,MAX('Assumptions'!$B$5-$B6,0),'Assumptions'!$B$5*EXP(-'Assumptions'!$B$9*(E$24/365))*NORMSDIST(-(((LN($B6/'Assumptions'!$B$5)+('Assumptions'!$B$9+0.5*'Assumptions'!$B$8^2)*(E$24/365))/('Assumptions'!$B$8*SQRT((E$24/365))))-'Assumptions'!$B$8*SQRT((E$24/365))))-$B6*NORMSDIST(-((LN($B6/'Assumptions'!$B$5)+('Assumptions'!$B$9+0.5*'Assumptions'!$B$8^2)*(E$24/365))/('Assumptions'!$B$8*SQRT((E$24/365)))))) | F6: =IF(F$24=0,MAX('Assumptions'!$B$5-$B6,0),'Assumptions'!$B$5*EXP(-'Assumptions'!$B$9*(F$24/365))*NORMSDIST(-(((LN($B6/'Assumptions'!$B$5)+('Assumptions'!$B$9+0.5*'Assumptions'!$B$8^2)*(F$24/365))/('Assumptions'!$B$8*SQRT((F$24/365))))-'Assumptions'!$B$8*SQRT((F$24/365))))-$B6*NORMSDIST(-((LN($B6/'Assumptions'!$B$5)+('Assumptions'!$B$9+0.5*'Assumptions'!$B$8^2)*(F$24/365))/('Assumptions'!$B$8*SQRT((F$24/365)))))) | G6: =IF(G$24=0,MAX('Assumptions'!$B$5-$B6,0),'Assumptions'!$B$5*EXP(-'Assumptions'!$B$9*(G$24/365))*NORMSDIST(-(((LN($B6/'Assumptions'!$B$5)+('Assumptions'!$B$9+0.5*'Assumptions'!$B$8^2)*(G$24/365))/('Assumptions'!$B$8*SQRT((G$24/365))))-'Assumptions'!$B$8*SQRT((G$24/365))))-$B6*NORMSDIST(-((LN($B6/'Assumptions'!$B$5)+('Assumptions'!$B$9+0.5*'Assumptions'!$B$8^2)*(G$24/365))/('Assumptions'!$B$8*SQRT((G$24/365)))))) | H6: =IF(H$24=0,MAX('Assumptions'!$B$5-$B6,0),'Assumptions'!$B$5*EXP(-'Assumptions'!$B$9*(H$24/365))*NORMSDIST(-(((LN($B6/'Assumptions'!$B$5)+('Assumptions'!$B$9+0.5*'Assumptions'!$B$8^2)*(H$24/365))/('Assumptions'!$B$8*SQRT((H$24/365))))-'Assumptions'!$B$8*SQRT((H$24/365))))-$B6*NORMSDIST(-((LN($B6/'Assumptions'!$B$5)+('Assumptions'!$B$9+0.5*'Assumptions'!$B$8^2)*(H$24/365))/('Assumptions'!$B$8*SQRT((H$24/365)))))) | I6: =IF(I$24=0,MAX('Assumptions'!$B$5-$B6,0),'Assumptions'!$B$5*EXP(-'Assumptions'!$B$9*(I$24/365))*NORMSDIST(-(((LN($B6/'Assumptions'!$B$5)+('Assumptions'!$B$9+0.5*'Assumptions'!$B$8^2)*(I$24/365))/('Assumptions'!$B$8*SQRT((I$24/365))))-'Assumptions'!$B$8*SQRT((I$24/365))))-$B6*NORMSDIST(-((LN($B6/'Assumptions'!$B$5)+('Assumptions'!$B$9+0.5*'Assumptions'!$B$8^2)*(I$24/365))/('Assumptions'!$B$8*SQRT((I$24/365)))))) | J6: =IF(J$24=0,MAX('Assumptions'!$B$5-$B6,0),'Assumptions'!$B$5*EXP(-'Assumptions'!$B$9*(J$24/365))*NORMSDIST(-(((LN($B6/'Assumptions'!$B$5)+('Assumptions'!$B$9+0.5*'Assumptions'!$B$8^2)*(J$24/365))/('Assumptions'!$B$8*SQRT((J$24/365))))-'Assumptions'!$B$8*SQRT((J$24/365))))-$B6*NORMSDIST(-((LN($B6/'Assumptions'!$B$5)+('Assumptions'!$B$9+0.5*'Assumptions'!$B$8^2)*(J$24/365))/('Assumptions'!$B$8*SQRT((J$24/365)))))) | ... U6: =IF(U$24=0,MAX('Assumptions'!$B$5-$B6,0),'Assumptions'!$B$5*EXP(-'Assumptions'!$B$9*(U$24/365))*NORMSDIST(-(((LN($B6/'Assumptions'!$B$5)+('Assumptions'!$B$9+0.5*'Assumptions'!$B$8^2)*(U$24/365))/('Assumptions'!$B$8*SQRT((U$24/365))))-'Assumptions'!$B$8*SQRT((U$24/365))))-$B6*NORMSDIST(-((LN($B6/'Assumptions'!$B$5)+('Assumptions'!$B$9+0.5*'Assumptions'!$B$8^2)*(U$24/365))/('Assumptions'!$B$8*SQRT((U$24/365))))))
A7: 0.04 | B7: ='Assumptions'!$B$4*(1-A7) | C7: =IF(C$24=0,MAX('Assumptions'!$B$5-$B7,0),'Assumptions'!$B$5*EXP(-'Assumptions'!$B$9*(C$24/365))*NORMSDIST(-(((LN($B7/'Assumptions'!$B$5)+('Assumptions'!$B$9+0.5*'Assumptions'!$B$8^2)*(C$24/365))/('Assumptions'!$B$8*SQRT((C$24/365))))-'Assumptions'!$B$8*SQRT((C$24/365))))-$B7*NORMSDIST(-((LN($B7/'Assumptions'!$B$5)+('Assumptions'!$B$9+0.5*'Assumptions'!$B$8^2)*(C$24/365))/('Assumptions'!$B$8*SQRT((C$24/365)))))) | D7: =IF(D$24=0,MAX('Assumptions'!$B$5-$B7,0),'Assumptions'!$B$5*EXP(-'Assumptions'!$B$9*(D$24/365))*NORMSDIST(-(((LN($B7/'Assumptions'!$B$5)+('Assumptions'!$B$9+0.5*'Assumptions'!$B$8^2)*(D$24/365))/('Assumptions'!$B$8*SQRT((D$24/365))))-'Assumptions'!$B$8*SQRT((D$24/365))))-$B7*NORMSDIST(-((LN($B7/'Assumptions'!$B$5)+('Assumptions'!$B$9+0.5*'Assumptions'!$B$8^2)*(D$24/365))/('Assumptions'!$B$8*SQRT((D$24/365)))))) | E7: =IF(E$24=0,MAX('Assumptions'!$B$5-$B7,0),'Assumptions'!$B$5*EXP(-'Assumptions'!$B$9*(E$24/365))*NORMSDIST(-(((LN($B7/'Assumptions'!$B$5)+('Assumptions'!$B$9+0.5*'Assumptions'!$B$8^2)*(E$24/365))/('Assumptions'!$B$8*SQRT((E$24/365))))-'Assumptions'!$B$8*SQRT((E$24/365))))-$B7*NORMSDIST(-((LN($B7/'Assumptions'!$B$5)+('Assumptions'!$B$9+0.5*'Assumptions'!$B$8^2)*(E$24/365))/('Assumptions'!$B$8*SQRT((E$24/365)))))) | F7: =IF(F$24=0,MAX('Assumptions'!$B$5-$B7,0),'Assumptions'!$B$5*EXP(-'Assumptions'!$B$9*(F$24/365))*NORMSDIST(-(((LN($B7/'Assumptions'!$B$5)+('Assumptions'!$B$9+0.5*'Assumptions'!$B$8^2)*(F$24/365))/('Assumptions'!$B$8*SQRT((F$24/365))))-'Assumptions'!$B$8*SQRT((F$24/365))))-$B7*NORMSDIST(-((LN($B7/'Assumptions'!$B$5)+('Assumptions'!$B$9+0.5*'Assumptions'!$B$8^2)*(F$24/365))/('Assumptions'!$B$8*SQRT((F$24/365)))))) | G7: =IF(G$24=0,MAX('Assumptions'!$B$5-$B7,0),'Assumptions'!$B$5*EXP(-'Assumptions'!$B$9*(G$24/365))*NORMSDIST(-(((LN($B7/'Assumptions'!$B$5)+('Assumptions'!$B$9+0.5*'Assumptions'!$B$8^2)*(G$24/365))/('Assumptions'!$B$8*SQRT((G$24/365))))-'Assumptions'!$B$8*SQRT((G$24/365))))-$B7*NORMSDIST(-((LN($B7/'Assumptions'!$B$5)+('Assumptions'!$B$9+0.5*'Assumptions'!$B$8^2)*(G$24/365))/('Assumptions'!$B$8*SQRT((G$24/365)))))) | H7: =IF(H$24=0,MAX('Assumptions'!$B$5-$B7,0),'Assumptions'!$B$5*EXP(-'Assumptions'!$B$9*(H$24/365))*NORMSDIST(-(((LN($B7/'Assumptions'!$B$5)+('Assumptions'!$B$9+0.5*'Assumptions'!$B$8^2)*(H$24/365))/('Assumptions'!$B$8*SQRT((H$24/365))))-'Assumptions'!$B$8*SQRT((H$24/365))))-$B7*NORMSDIST(-((LN($B7/'Assumptions'!$B$5)+('Assumptions'!$B$9+0.5*'Assumptions'!$B$8^2)*(H$24/365))/('Assumptions'!$B$8*SQRT((H$24/365)))))) | I7: =IF(I$24=0,MAX('Assumptions'!$B$5-$B7,0),'Assumptions'!$B$5*EXP(-'Assumptions'!$B$9*(I$24/365))*NORMSDIST(-(((LN($B7/'Assumptions'!$B$5)+('Assumptions'!$B$9+0.5*'Assumptions'!$B$8^2)*(I$24/365))/('Assumptions'!$B$8*SQRT((I$24/365))))-'Assumptions'!$B$8*SQRT((I$24/365))))-$B7*NORMSDIST(-((LN($B7/'Assumptions'!$B$5)+('Assumptions'!$B$9+0.5*'Assumptions'!$B$8^2)*(I$24/365))/('Assumptions'!$B$8*SQRT((I$24/365)))))) | J7: =IF(J$24=0,MAX('Assumptions'!$B$5-$B7,0),'Assumptions'!$B$5*EXP(-'Assumptions'!$B$9*(J$24/365))*NORMSDIST(-(((LN($B7/'Assumptions'!$B$5)+('Assumptions'!$B$9+0.5*'Assumptions'!$B$8^2)*(J$24/365))/('Assumptions'!$B$8*SQRT((J$24/365))))-'Assumptions'!$B$8*SQRT((J$24/365))))-$B7*NORMSDIST(-((LN($B7/'Assumptions'!$B$5)+('Assumptions'!$B$9+0.5*'Assumptions'!$B$8^2)*(J$24/365))/('Assumptions'!$B$8*SQRT((J$24/365)))))) | ... U7: =IF(U$24=0,MAX('Assumptions'!$B$5-$B7,0),'Assumptions'!$B$5*EXP(-'Assumptions'!$B$9*(U$24/365))*NORMSDIST(-(((LN($B7/'Assumptions'!$B$5)+('Assumptions'!$B$9+0.5*'Assumptions'!$B$8^2)*(U$24/365))/('Assumptions'!$B$8*SQRT((U$24/365))))-'Assumptions'!$B$8*SQRT((U$24/365))))-$B7*NORMSDIST(-((LN($B7/'Assumptions'!$B$5)+('Assumptions'!$B$9+0.5*'Assumptions'!$B$8^2)*(U$24/365))/('Assumptions'!$B$8*SQRT((U$24/365))))))
A8: 0.05 | B8: ='Assumptions'!$B$4*(1-A8) | C8: =IF(C$24=0,MAX('Assumptions'!$B$5-$B8,0),'Assumptions'!$B$5*EXP(-'Assumptions'!$B$9*(C$24/365))*NORMSDIST(-(((LN($B8/'Assumptions'!$B$5)+('Assumptions'!$B$9+0.5*'Assumptions'!$B$8^2)*(C$24/365))/('Assumptions'!$B$8*SQRT((C$24/365))))-'Assumptions'!$B$8*SQRT((C$24/365))))-$B8*NORMSDIST(-((LN($B8/'Assumptions'!$B$5)+('Assumptions'!$B$9+0.5*'Assumptions'!$B$8^2)*(C$24/365))/('Assumptions'!$B$8*SQRT((C$24/365)))))) | D8: =IF(D$24=0,MAX('Assumptions'!$B$5-$B8,0),'Assumptions'!$B$5*EXP(-'Assumptions'!$B$9*(D$24/365))*NORMSDIST(-(((LN($B8/'Assumptions'!$B$5)+('Assumptions'!$B$9+0.5*'Assumptions'!$B$8^2)*(D$24/365))/('Assumptions'!$B$8*SQRT((D$24/365))))-'Assumptions'!$B$8*SQRT((D$24/365))))-$B8*NORMSDIST(-((LN($B8/'Assumptions'!$B$5)+('Assumptions'!$B$9+0.5*'Assumptions'!$B$8^2)*(D$24/365))/('Assumptions'!$B$8*SQRT((D$24/365)))))) | E8: =IF(E$24=0,MAX('Assumptions'!$B$5-$B8,0),'Assumptions'!$B$5*EXP(-'Assumptions'!$B$9*(E$24/365))*NORMSDIST(-(((LN($B8/'Assumptions'!$B$5)+('Assumptions'!$B$9+0.5*'Assumptions'!$B$8^2)*(E$24/365))/('Assumptions'!$B$8*SQRT((E$24/365))))-'Assumptions'!$B$8*SQRT((E$24/365))))-$B8*NORMSDIST(-((LN($B8/'Assumptions'!$B$5)+('Assumptions'!$B$9+0.5*'Assumptions'!$B$8^2)*(E$24/365))/('Assumptions'!$B$8*SQRT((E$24/365)))))) | F8: =IF(F$24=0,MAX('Assumptions'!$B$5-$B8,0),'Assumptions'!$B$5*EXP(-'Assumptions'!$B$9*(F$24/365))*NORMSDIST(-(((LN($B8/'Assumptions'!$B$5)+('Assumptions'!$B$9+0.5*'Assumptions'!$B$8^2)*(F$24/365))/('Assumptions'!$B$8*SQRT((F$24/365))))-'Assumptions'!$B$8*SQRT((F$24/365))))-$B8*NORMSDIST(-((LN($B8/'Assumptions'!$B$5)+('Assumptions'!$B$9+0.5*'Assumptions'!$B$8^2)*(F$24/365))/('Assumptions'!$B$8*SQRT((F$24/365)))))) | G8: =IF(G$24=0,MAX('Assumptions'!$B$5-$B8,0),'Assumptions'!$B$5*EXP(-'Assumptions'!$B$9*(G$24/365))*NORMSDIST(-(((LN($B8/'Assumptions'!$B$5)+('Assumptions'!$B$9+0.5*'Assumptions'!$B$8^2)*(G$24/365))/('Assumptions'!$B$8*SQRT((G$24/365))))-'Assumptions'!$B$8*SQRT((G$24/365))))-$B8*NORMSDIST(-((LN($B8/'Assumptions'!$B$5)+('Assumptions'!$B$9+0.5*'Assumptions'!$B$8^2)*(G$24/365))/('Assumptions'!$B$8*SQRT((G$24/365)))))) | H8: =IF(H$24=0,MAX('Assumptions'!$B$5-$B8,0),'Assumptions'!$B$5*EXP(-'Assumptions'!$B$9*(H$24/365))*NORMSDIST(-(((LN($B8/'Assumptions'!$B$5)+('Assumptions'!$B$9+0.5*'Assumptions'!$B$8^2)*(H$24/365))/('Assumptions'!$B$8*SQRT((H$24/365))))-'Assumptions'!$B$8*SQRT((H$24/365))))-$B8*NORMSDIST(-((LN($B8/'Assumptions'!$B$5)+('Assumptions'!$B$9+0.5*'Assumptions'!$B$8^2)*(H$24/365))/('Assumptions'!$B$8*SQRT((H$24/365)))))) | I8: =IF(I$24=0,MAX('Assumptions'!$B$5-$B8,0),'Assumptions'!$B$5*EXP(-'Assumptions'!$B$9*(I$24/365))*NORMSDIST(-(((LN($B8/'Assumptions'!$B$5)+('Assumptions'!$B$9+0.5*'Assumptions'!$B$8^2)*(I$24/365))/('Assumptions'!$B$8*SQRT((I$24/365))))-'Assumptions'!$B$8*SQRT((I$24/365))))-$B8*NORMSDIST(-((LN($B8/'Assumptions'!$B$5)+('Assumptions'!$B$9+0.5*'Assumptions'!$B$8^2)*(I$24/365))/('Assumptions'!$B$8*SQRT((I$24/365)))))) | J8: =IF(J$24=0,MAX('Assumptions'!$B$5-$B8,0),'Assumptions'!$B$5*EXP(-'Assumptions'!$B$9*(J$24/365))*NORMSDIST(-(((LN($B8/'Assumptions'!$B$5)+('Assumptions'!$B$9+0.5*'Assumptions'!$B$8^2)*(J$24/365))/('Assumptions'!$B$8*SQRT((J$24/365))))-'Assumptions'!$B$8*SQRT((J$24/365))))-$B8*NORMSDIST(-((LN($B8/'Assumptions'!$B$5)+('Assumptions'!$B$9+0.5*'Assumptions'!$B$8^2)*(J$24/365))/('Assumptions'!$B$8*SQRT((J$24/365)))))) | ... U8: =IF(U$24=0,MAX('Assumptions'!$B$5-$B8,0),'Assumptions'!$B$5*EXP(-'Assumptions'!$B$9*(U$24/365))*NORMSDIST(-(((LN($B8/'Assumptions'!$B$5)+('Assumptions'!$B$9+0.5*'Assumptions'!$B$8^2)*(U$24/365))/('Assumptions'!$B$8*SQRT((U$24/365))))-'Assumptions'!$B$8*SQRT((U$24/365))))-$B8*NORMSDIST(-((LN($B8/'Assumptions'!$B$5)+('Assumptions'!$B$9+0.5*'Assumptions'!$B$8^2)*(U$24/365))/('Assumptions'!$B$8*SQRT((U$24/365))))))
A9: 0.06 | B9: ='Assumptions'!$B$4*(1-A9) | C9: =IF(C$24=0,MAX('Assumptions'!$B$5-$B9,0),'Assumptions'!$B$5*EXP(-'Assumptions'!$B$9*(C$24/365))*NORMSDIST(-(((LN($B9/'Assumptions'!$B$5)+('Assumptions'!$B$9+0.5*'Assumptions'!$B$8^2)*(C$24/365))/('Assumptions'!$B$8*SQRT((C$24/365))))-'Assumptions'!$B$8*SQRT((C$24/365))))-$B9*NORMSDIST(-((LN($B9/'Assumptions'!$B$5)+('Assumptions'!$B$9+0.5*'Assumptions'!$B$8^2)*(C$24/365))/('Assumptions'!$B$8*SQRT((C$24/365)))))) | D9: =IF(D$24=0,MAX('Assumptions'!$B$5-$B9,0),'Assumptions'!$B$5*EXP(-'Assumptions'!$B$9*(D$24/365))*NORMSDIST(-(((LN($B9/'Assumptions'!$B$5)+('Assumptions'!$B$9+0.5*'Assumptions'!$B$8^2)*(D$24/365))/('Assumptions'!$B$8*SQRT((D$24/365))))-'Assumptions'!$B$8*SQRT((D$24/365))))-$B9*NORMSDIST(-((LN($B9/'Assumptions'!$B$5)+('Assumptions'!$B$9+0.5*'Assumptions'!$B$8^2)*(D$24/365))/('Assumptions'!$B$8*SQRT((D$24/365)))))) | E9: =IF(E$24=0,MAX('Assumptions'!$B$5-$B9,0),'Assumptions'!$B$5*EXP(-'Assumptions'!$B$9*(E$24/365))*NORMSDIST(-(((LN($B9/'Assumptions'!$B$5)+('Assumptions'!$B$9+0.5*'Assumptions'!$B$8^2)*(E$24/365))/('Assumptions'!$B$8*SQRT((E$24/365))))-'Assumptions'!$B$8*SQRT((E$24/365))))-$B9*NORMSDIST(-((LN($B9/'Assumptions'!$B$5)+('Assumptions'!$B$9+0.5*'Assumptions'!$B$8^2)*(E$24/365))/('Assumptions'!$B$8*SQRT((E$24/365)))))) | F9: =IF(F$24=0,MAX('Assumptions'!$B$5-$B9,0),'Assumptions'!$B$5*EXP(-'Assumptions'!$B$9*(F$24/365))*NORMSDIST(-(((LN($B9/'Assumptions'!$B$5)+('Assumptions'!$B$9+0.5*'Assumptions'!$B$8^2)*(F$24/365))/('Assumptions'!$B$8*SQRT((F$24/365))))-'Assumptions'!$B$8*SQRT((F$24/365))))-$B9*NORMSDIST(-((LN($B9/'Assumptions'!$B$5)+('Assumptions'!$B$9+0.5*'Assumptions'!$B$8^2)*(F$24/365))/('Assumptions'!$B$8*SQRT((F$24/365)))))) | G9: =IF(G$24=0,MAX('Assumptions'!$B$5-$B9,0),'Assumptions'!$B$5*EXP(-'Assumptions'!$B$9*(G$24/365))*NORMSDIST(-(((LN($B9/'Assumptions'!$B$5)+('Assumptions'!$B$9+0.5*'Assumptions'!$B$8^2)*(G$24/365))/('Assumptions'!$B$8*SQRT((G$24/365))))-'Assumptions'!$B$8*SQRT((G$24/365))))-$B9*NORMSDIST(-((LN($B9/'Assumptions'!$B$5)+('Assumptions'!$B$9+0.5*'Assumptions'!$B$8^2)*(G$24/365))/('Assumptions'!$B$8*SQRT((G$24/365)))))) | H9: =IF(H$24=0,MAX('Assumptions'!$B$5-$B9,0),'Assumptions'!$B$5*EXP(-'Assumptions'!$B$9*(H$24/365))*NORMSDIST(-(((LN($B9/'Assumptions'!$B$5)+('Assumptions'!$B$9+0.5*'Assumptions'!$B$8^2)*(H$24/365))/('Assumptions'!$B$8*SQRT((H$24/365))))-'Assumptions'!$B$8*SQRT((H$24/365))))-$B9*NORMSDIST(-((LN($B9/'Assumptions'!$B$5)+('Assumptions'!$B$9+0.5*'Assumptions'!$B$8^2)*(H$24/365))/('Assumptions'!$B$8*SQRT((H$24/365)))))) | I9: =IF(I$24=0,MAX('Assumptions'!$B$5-$B9,0),'Assumptions'!$B$5*EXP(-'Assumptions'!$B$9*(I$24/365))*NORMSDIST(-(((LN($B9/'Assumptions'!$B$5)+('Assumptions'!$B$9+0.5*'Assumptions'!$B$8^2)*(I$24/365))/('Assumptions'!$B$8*SQRT((I$24/365))))-'Assumptions'!$B$8*SQRT((I$24/365))))-$B9*NORMSDIST(-((LN($B9/'Assumptions'!$B$5)+('Assumptions'!$B$9+0.5*'Assumptions'!$B$8^2)*(I$24/365))/('Assumptions'!$B$8*SQRT((I$24/365)))))) | J9: =IF(J$24=0,MAX('Assumptions'!$B$5-$B9,0),'Assumptions'!$B$5*EXP(-'Assumptions'!$B$9*(J$24/365))*NORMSDIST(-(((LN($B9/'Assumptions'!$B$5)+('Assumptions'!$B$9+0.5*'Assumptions'!$B$8^2)*(J$24/365))/('Assumptions'!$B$8*SQRT((J$24/365))))-'Assumptions'!$B$8*SQRT((J$24/365))))-$B9*NORMSDIST(-((LN($B9/'Assumptions'!$B$5)+('Assumptions'!$B$9+0.5*'Assumptions'!$B$8^2)*(J$24/365))/('Assumptions'!$B$8*SQRT((J$24/365)))))) | ... U9: =IF(U$24=0,MAX('Assumptions'!$B$5-$B9,0),'Assumptions'!$B$5*EXP(-'Assumptions'!$B$9*(U$24/365))*NORMSDIST(-(((LN($B9/'Assumptions'!$B$5)+('Assumptions'!$B$9+0.5*'Assumptions'!$B$8^2)*(U$24/365))/('Assumptions'!$B$8*SQRT((U$24/365))))-'Assumptions'!$B$8*SQRT((U$24/365))))-$B9*NORMSDIST(-((LN($B9/'Assumptions'!$B$5)+('Assumptions'!$B$9+0.5*'Assumptions'!$B$8^2)*(U$24/365))/('Assumptions'!$B$8*SQRT((U$24/365))))))
A10: 0.07 | B10: ='Assumptions'!$B$4*(1-A10) | C10: =IF(C$24=0,MAX('Assumptions'!$B$5-$B10,0),'Assumptions'!$B$5*EXP(-'Assumptions'!$B$9*(C$24/365))*NORMSDIST(-(((LN($B10/'Assumptions'!$B$5)+('Assumptions'!$B$9+0.5*'Assumptions'!$B$8^2)*(C$24/365))/('Assumptions'!$B$8*SQRT((C$24/365))))-'Assumptions'!$B$8*SQRT((C$24/365))))-$B10*NORMSDIST(-((LN($B10/'Assumptions'!$B$5)+('Assumptions'!$B$9+0.5*'Assumptions'!$B$8^2)*(C$24/365))/('Assumptions'!$B$8*SQRT((C$24/365)))))) | D10: =IF(D$24=0,MAX('Assumptions'!$B$5-$B10,0),'Assumptions'!$B$5*EXP(-'Assumptions'!$B$9*(D$24/365))*NORMSDIST(-(((LN($B10/'Assumptions'!$B$5)+('Assumptions'!$B$9+0.5*'Assumptions'!$B$8^2)*(D$24/365))/('Assumptions'!$B$8*SQRT((D$24/365))))-'Assumptions'!$B$8*SQRT((D$24/365))))-$B10*NORMSDIST(-((LN($B10/'Assumptions'!$B$5)+('Assumptions'!$B$9+0.5*'Assumptions'!$B$8^2)*(D$24/365))/('Assumptions'!$B$8*SQRT((D$24/365)))))) | E10: =IF(E$24=0,MAX('Assumptions'!$B$5-$B10,0),'Assumptions'!$B$5*EXP(-'Assumptions'!$B$9*(E$24/365))*NORMSDIST(-(((LN($B10/'Assumptions'!$B$5)+('Assumptions'!$B$9+0.5*'Assumptions'!$B$8^2)*(E$24/365))/('Assumptions'!$B$8*SQRT((E$24/365))))-'Assumptions'!$B$8*SQRT((E$24/365))))-$B10*NORMSDIST(-((LN($B10/'Assumptions'!$B$5)+('Assumptions'!$B$9+0.5*'Assumptions'!$B$8^2)*(E$24/365))/('Assumptions'!$B$8*SQRT((E$24/365)))))) | F10: =IF(F$24=0,MAX('Assumptions'!$B$5-$B10,0),'Assumptions'!$B$5*EXP(-'Assumptions'!$B$9*(F$24/365))*NORMSDIST(-(((LN($B10/'Assumptions'!$B$5)+('Assumptions'!$B$9+0.5*'Assumptions'!$B$8^2)*(F$24/365))/('Assumptions'!$B$8*SQRT((F$24/365))))-'Assumptions'!$B$8*SQRT((F$24/365))))-$B10*NORMSDIST(-((LN($B10/'Assumptions'!$B$5)+('Assumptions'!$B$9+0.5*'Assumptions'!$B$8^2)*(F$24/365))/('Assumptions'!$B$8*SQRT((F$24/365)))))) | G10: =IF(G$24=0,MAX('Assumptions'!$B$5-$B10,0),'Assumptions'!$B$5*EXP(-'Assumptions'!$B$9*(G$24/365))*NORMSDIST(-(((LN($B10/'Assumptions'!$B$5)+('Assumptions'!$B$9+0.5*'Assumptions'!$B$8^2)*(G$24/365))/('Assumptions'!$B$8*SQRT((G$24/365))))-'Assumptions'!$B$8*SQRT((G$24/365))))-$B10*NORMSDIST(-((LN($B10/'Assumptions'!$B$5)+('Assumptions'!$B$9+0.5*'Assumptions'!$B$8^2)*(G$24/365))/('Assumptions'!$B$8*SQRT((G$24/365)))))) | H10: =IF(H$24=0,MAX('Assumptions'!$B$5-$B10,0),'Assumptions'!$B$5*EXP(-'Assumptions'!$B$9*(H$24/365))*NORMSDIST(-(((LN($B10/'Assumptions'!$B$5)+('Assumptions'!$B$9+0.5*'Assumptions'!$B$8^2)*(H$24/365))/('Assumptions'!$B$8*SQRT((H$24/365))))-'Assumptions'!$B$8*SQRT((H$24/365))))-$B10*NORMSDIST(-((LN($B10/'Assumptions'!$B$5)+('Assumptions'!$B$9+0.5*'Assumptions'!$B$8^2)*(H$24/365))/('Assumptions'!$B$8*SQRT((H$24/365)))))) | I10: =IF(I$24=0,MAX('Assumptions'!$B$5-$B10,0),'Assumptions'!$B$5*EXP(-'Assumptions'!$B$9*(I$24/365))*NORMSDIST(-(((LN($B10/'Assumptions'!$B$5)+('Assumptions'!$B$9+0.5*'Assumptions'!$B$8^2)*(I$24/365))/('Assumptions'!$B$8*SQRT((I$24/365))))-'Assumptions'!$B$8*SQRT((I$24/365))))-$B10*NORMSDIST(-((LN($B10/'Assumptions'!$B$5)+('Assumptions'!$B$9+0.5*'Assumptions'!$B$8^2)*(I$24/365))/('Assumptions'!$B$8*SQRT((I$24/365)))))) | J10: =IF(J$24=0,MAX('Assumptions'!$B$5-$B10,0),'Assumptions'!$B$5*EXP(-'Assumptions'!$B$9*(J$24/365))*NORMSDIST(-(((LN($B10/'Assumptions'!$B$5)+('Assumptions'!$B$9+0.5*'Assumptions'!$B$8^2)*(J$24/365))/('Assumptions'!$B$8*SQRT((J$24/365))))-'Assumptions'!$B$8*SQRT((J$24/365))))-$B10*NORMSDIST(-((LN($B10/'Assumptions'!$B$5)+('Assumptions'!$B$9+0.5*'Assumptions'!$B$8^2)*(J$24/365))/('Assumptions'!$B$8*SQRT((J$24/365)))))) | ... U10: =IF(U$24=0,MAX('Assumptions'!$B$5-$B10,0),'Assumptions'!$B$5*EXP(-'Assumptions'!$B$9*(U$24/365))*NORMSDIST(-(((LN($B10/'Assumptions'!$B$5)+('Assumptions'!$B$9+0.5*'Assumptions'!$B$8^2)*(U$24/365))/('Assumptions'!$B$8*SQRT((U$24/365))))-'Assumptions'!$B$8*SQRT((U$24/365))))-$B10*NORMSDIST(-((LN($B10/'Assumptions'!$B$5)+('Assumptions'!$B$9+0.5*'Assumptions'!$B$8^2)*(U$24/365))/('Assumptions'!$B$8*SQRT((U$24/365))))))
A11: 0.08 | B11: ='Assumptions'!$B$4*(1-A11) | C11: =IF(C$24=0,MAX('Assumptions'!$B$5-$B11,0),'Assumptions'!$B$5*EXP(-'Assumptions'!$B$9*(C$24/365))*NORMSDIST(-(((LN($B11/'Assumptions'!$B$5)+('Assumptions'!$B$9+0.5*'Assumptions'!$B$8^2)*(C$24/365))/('Assumptions'!$B$8*SQRT((C$24/365))))-'Assumptions'!$B$8*SQRT((C$24/365))))-$B11*NORMSDIST(-((LN($B11/'Assumptions'!$B$5)+('Assumptions'!$B$9+0.5*'Assumptions'!$B$8^2)*(C$24/365))/('Assumptions'!$B$8*SQRT((C$24/365)))))) | D11: =IF(D$24=0,MAX('Assumptions'!$B$5-$B11,0),'Assumptions'!$B$5*EXP(-'Assumptions'!$B$9*(D$24/365))*NORMSDIST(-(((LN($B11/'Assumptions'!$B$5)+('Assumptions'!$B$9+0.5*'Assumptions'!$B$8^2)*(D$24/365))/('Assumptions'!$B$8*SQRT((D$24/365))))-'Assumptions'!$B$8*SQRT((D$24/365))))-$B11*NORMSDIST(-((LN($B11/'Assumptions'!$B$5)+('Assumptions'!$B$9+0.5*'Assumptions'!$B$8^2)*(D$24/365))/('Assumptions'!$B$8*SQRT((D$24/365)))))) | E11: =IF(E$24=0,MAX('Assumptions'!$B$5-$B11,0),'Assumptions'!$B$5*EXP(-'Assumptions'!$B$9*(E$24/365))*NORMSDIST(-(((LN($B11/'Assumptions'!$B$5)+('Assumptions'!$B$9+0.5*'Assumptions'!$B$8^2)*(E$24/365))/('Assumptions'!$B$8*SQRT((E$24/365))))-'Assumptions'!$B$8*SQRT((E$24/365))))-$B11*NORMSDIST(-((LN($B11/'Assumptions'!$B$5)+('Assumptions'!$B$9+0.5*'Assumptions'!$B$8^2)*(E$24/365))/('Assumptions'!$B$8*SQRT((E$24/365)))))) | F11: =IF(F$24=0,MAX('Assumptions'!$B$5-$B11,0),'Assumptions'!$B$5*EXP(-'Assumptions'!$B$9*(F$24/365))*NORMSDIST(-(((LN($B11/'Assumptions'!$B$5)+('Assumptions'!$B$9+0.5*'Assumptions'!$B$8^2)*(F$24/365))/('Assumptions'!$B$8*SQRT((F$24/365))))-'Assumptions'!$B$8*SQRT((F$24/365))))-$B11*NORMSDIST(-((LN($B11/'Assumptions'!$B$5)+('Assumptions'!$B$9+0.5*'Assumptions'!$B$8^2)*(F$24/365))/('Assumptions'!$B$8*SQRT((F$24/365)))))) | G11: =IF(G$24=0,MAX('Assumptions'!$B$5-$B11,0),'Assumptions'!$B$5*EXP(-'Assumptions'!$B$9*(G$24/365))*NORMSDIST(-(((LN($B11/'Assumptions'!$B$5)+('Assumptions'!$B$9+0.5*'Assumptions'!$B$8^2)*(G$24/365))/('Assumptions'!$B$8*SQRT((G$24/365))))-'Assumptions'!$B$8*SQRT((G$24/365))))-$B11*NORMSDIST(-((LN($B11/'Assumptions'!$B$5)+('Assumptions'!$B$9+0.5*'Assumptions'!$B$8^2)*(G$24/365))/('Assumptions'!$B$8*SQRT((G$24/365)))))) | H11: =IF(H$24=0,MAX('Assumptions'!$B$5-$B11,0),'Assumptions'!$B$5*EXP(-'Assumptions'!$B$9*(H$24/365))*NORMSDIST(-(((LN($B11/'Assumptions'!$B$5)+('Assumptions'!$B$9+0.5*'Assumptions'!$B$8^2)*(H$24/365))/('Assumptions'!$B$8*SQRT((H$24/365))))-'Assumptions'!$B$8*SQRT((H$24/365))))-$B11*NORMSDIST(-((LN($B11/'Assumptions'!$B$5)+('Assumptions'!$B$9+0.5*'Assumptions'!$B$8^2)*(H$24/365))/('Assumptions'!$B$8*SQRT((H$24/365)))))) | I11: =IF(I$24=0,MAX('Assumptions'!$B$5-$B11,0),'Assumptions'!$B$5*EXP(-'Assumptions'!$B$9*(I$24/365))*NORMSDIST(-(((LN($B11/'Assumptions'!$B$5)+('Assumptions'!$B$9+0.5*'Assumptions'!$B$8^2)*(I$24/365))/('Assumptions'!$B$8*SQRT((I$24/365))))-'Assumptions'!$B$8*SQRT((I$24/365))))-$B11*NORMSDIST(-((LN($B11/'Assumptions'!$B$5)+('Assumptions'!$B$9+0.5*'Assumptions'!$B$8^2)*(I$24/365))/('Assumptions'!$B$8*SQRT((I$24/365)))))) | J11: =IF(J$24=0,MAX('Assumptions'!$B$5-$B11,0),'Assumptions'!$B$5*EXP(-'Assumptions'!$B$9*(J$24/365))*NORMSDIST(-(((LN($B11/'Assumptions'!$B$5)+('Assumptions'!$B$9+0.5*'Assumptions'!$B$8^2)*(J$24/365))/('Assumptions'!$B$8*SQRT((J$24/365))))-'Assumptions'!$B$8*SQRT((J$24/365))))-$B11*NORMSDIST(-((LN($B11/'Assumptions'!$B$5)+('Assumptions'!$B$9+0.5*'Assumptions'!$B$8^2)*(J$24/365))/('Assumptions'!$B$8*SQRT((J$24/365)))))) | ... U11: =IF(U$24=0,MAX('Assumptions'!$B$5-$B11,0),'Assumptions'!$B$5*EXP(-'Assumptions'!$B$9*(U$24/365))*NORMSDIST(-(((LN($B11/'Assumptions'!$B$5)+('Assumptions'!$B$9+0.5*'Assumptions'!$B$8^2)*(U$24/365))/('Assumptions'!$B$8*SQRT((U$24/365))))-'Assumptions'!$B$8*SQRT((U$24/365))))-$B11*NORMSDIST(-((LN($B11/'Assumptions'!$B$5)+('Assumptions'!$B$9+0.5*'Assumptions'!$B$8^2)*(U$24/365))/('Assumptions'!$B$8*SQRT((U$24/365))))))
A12: 0.09 | B12: ='Assumptions'!$B$4*(1-A12) | C12: =IF(C$24=0,MAX('Assumptions'!$B$5-$B12,0),'Assumptions'!$B$5*EXP(-'Assumptions'!$B$9*(C$24/365))*NORMSDIST(-(((LN($B12/'Assumptions'!$B$5)+('Assumptions'!$B$9+0.5*'Assumptions'!$B$8^2)*(C$24/365))/('Assumptions'!$B$8*SQRT((C$24/365))))-'Assumptions'!$B$8*SQRT((C$24/365))))-$B12*NORMSDIST(-((LN($B12/'Assumptions'!$B$5)+('Assumptions'!$B$9+0.5*'Assumptions'!$B$8^2)*(C$24/365))/('Assumptions'!$B$8*SQRT((C$24/365)))))) | D12: =IF(D$24=0,MAX('Assumptions'!$B$5-$B12,0),'Assumptions'!$B$5*EXP(-'Assumptions'!$B$9*(D$24/365))*NORMSDIST(-(((LN($B12/'Assumptions'!$B$5)+('Assumptions'!$B$9+0.5*'Assumptions'!$B$8^2)*(D$24/365))/('Assumptions'!$B$8*SQRT((D$24/365))))-'Assumptions'!$B$8*SQRT((D$24/365))))-$B12*NORMSDIST(-((LN($B12/'Assumptions'!$B$5)+('Assumptions'!$B$9+0.5*'Assumptions'!$B$8^2)*(D$24/365))/('Assumptions'!$B$8*SQRT((D$24/365)))))) | E12: =IF(E$24=0,MAX('Assumptions'!$B$5-$B12,0),'Assumptions'!$B$5*EXP(-'Assumptions'!$B$9*(E$24/365))*NORMSDIST(-(((LN($B12/'Assumptions'!$B$5)+('Assumptions'!$B$9+0.5*'Assumptions'!$B$8^2)*(E$24/365))/('Assumptions'!$B$8*SQRT((E$24/365))))-'Assumptions'!$B$8*SQRT((E$24/365))))-$B12*NORMSDIST(-((LN($B12/'Assumptions'!$B$5)+('Assumptions'!$B$9+0.5*'Assumptions'!$B$8^2)*(E$24/365))/('Assumptions'!$B$8*SQRT((E$24/365)))))) | F12: =IF(F$24=0,MAX('Assumptions'!$B$5-$B12,0),'Assumptions'!$B$5*EXP(-'Assumptions'!$B$9*(F$24/365))*NORMSDIST(-(((LN($B12/'Assumptions'!$B$5)+('Assumptions'!$B$9+0.5*'Assumptions'!$B$8^2)*(F$24/365))/('Assumptions'!$B$8*SQRT((F$24/365))))-'Assumptions'!$B$8*SQRT((F$24/365))))-$B12*NORMSDIST(-((LN($B12/'Assumptions'!$B$5)+('Assumptions'!$B$9+0.5*'Assumptions'!$B$8^2)*(F$24/365))/('Assumptions'!$B$8*SQRT((F$24/365)))))) | G12: =IF(G$24=0,MAX('Assumptions'!$B$5-$B12,0),'Assumptions'!$B$5*EXP(-'Assumptions'!$B$9*(G$24/365))*NORMSDIST(-(((LN($B12/'Assumptions'!$B$5)+('Assumptions'!$B$9+0.5*'Assumptions'!$B$8^2)*(G$24/365))/('Assumptions'!$B$8*SQRT((G$24/365))))-'Assumptions'!$B$8*SQRT((G$24/365))))-$B12*NORMSDIST(-((LN($B12/'Assumptions'!$B$5)+('Assumptions'!$B$9+0.5*'Assumptions'!$B$8^2)*(G$24/365))/('Assumptions'!$B$8*SQRT((G$24/365)))))) | H12: =IF(H$24=0,MAX('Assumptions'!$B$5-$B12,0),'Assumptions'!$B$5*EXP(-'Assumptions'!$B$9*(H$24/365))*NORMSDIST(-(((LN($B12/'Assumptions'!$B$5)+('Assumptions'!$B$9+0.5*'Assumptions'!$B$8^2)*(H$24/365))/('Assumptions'!$B$8*SQRT((H$24/365))))-'Assumptions'!$B$8*SQRT((H$24/365))))-$B12*NORMSDIST(-((LN($B12/'Assumptions'!$B$5)+('Assumptions'!$B$9+0.5*'Assumptions'!$B$8^2)*(H$24/365))/('Assumptions'!$B$8*SQRT((H$24/365)))))) | I12: =IF(I$24=0,MAX('Assumptions'!$B$5-$B12,0),'Assumptions'!$B$5*EXP(-'Assumptions'!$B$9*(I$24/365))*NORMSDIST(-(((LN($B12/'Assumptions'!$B$5)+('Assumptions'!$B$9+0.5*'Assumptions'!$B$8^2)*(I$24/365))/('Assumptions'!$B$8*SQRT((I$24/365))))-'Assumptions'!$B$8*SQRT((I$24/365))))-$B12*NORMSDIST(-((LN($B12/'Assumptions'!$B$5)+('Assumptions'!$B$9+0.5*'Assumptions'!$B$8^2)*(I$24/365))/('Assumptions'!$B$8*SQRT((I$24/365)))))) | J12: =IF(J$24=0,MAX('Assumptions'!$B$5-$B12,0),'Assumptions'!$B$5*EXP(-'Assumptions'!$B$9*(J$24/365))*NORMSDIST(-(((LN($B12/'Assumptions'!$B$5)+('Assumptions'!$B$9+0.5*'Assumptions'!$B$8^2)*(J$24/365))/('Assumptions'!$B$8*SQRT((J$24/365))))-'Assumptions'!$B$8*SQRT((J$24/365))))-$B12*NORMSDIST(-((LN($B12/'Assumptions'!$B$5)+('Assumptions'!$B$9+0.5*'Assumptions'!$B$8^2)*(J$24/365))/('Assumptions'!$B$8*SQRT((J$24/365)))))) | ... U12: =IF(U$24=0,MAX('Assumptions'!$B$5-$B12,0),'Assumptions'!$B$5*EXP(-'Assumptions'!$B$9*(U$24/365))*NORMSDIST(-(((LN($B12/'Assumptions'!$B$5)+('Assumptions'!$B$9+0.5*'Assumptions'!$B$8^2)*(U$24/365))/('Assumptions'!$B$8*SQRT((U$24/365))))-'Assumptions'!$B$8*SQRT((U$24/365))))-$B12*NORMSDIST(-((LN($B12/'Assumptions'!$B$5)+('Assumptions'!$B$9+0.5*'Assumptions'!$B$8^2)*(U$24/365))/('Assumptions'!$B$8*SQRT((U$24/365))))))
A13: 0.1 | B13: ='Assumptions'!$B$4*(1-A13) | C13: =IF(C$24=0,MAX('Assumptions'!$B$5-$B13,0),'Assumptions'!$B$5*EXP(-'Assumptions'!$B$9*(C$24/365))*NORMSDIST(-(((LN($B13/'Assumptions'!$B$5)+('Assumptions'!$B$9+0.5*'Assumptions'!$B$8^2)*(C$24/365))/('Assumptions'!$B$8*SQRT((C$24/365))))-'Assumptions'!$B$8*SQRT((C$24/365))))-$B13*NORMSDIST(-((LN($B13/'Assumptions'!$B$5)+('Assumptions'!$B$9+0.5*'Assumptions'!$B$8^2)*(C$24/365))/('Assumptions'!$B$8*SQRT((C$24/365)))))) | D13: =IF(D$24=0,MAX('Assumptions'!$B$5-$B13,0),'Assumptions'!$B$5*EXP(-'Assumptions'!$B$9*(D$24/365))*NORMSDIST(-(((LN($B13/'Assumptions'!$B$5)+('Assumptions'!$B$9+0.5*'Assumptions'!$B$8^2)*(D$24/365))/('Assumptions'!$B$8*SQRT((D$24/365))))-'Assumptions'!$B$8*SQRT((D$24/365))))-$B13*NORMSDIST(-((LN($B13/'Assumptions'!$B$5)+('Assumptions'!$B$9+0.5*'Assumptions'!$B$8^2)*(D$24/365))/('Assumptions'!$B$8*SQRT((D$24/365)))))) | E13: =IF(E$24=0,MAX('Assumptions'!$B$5-$B13,0),'Assumptions'!$B$5*EXP(-'Assumptions'!$B$9*(E$24/365))*NORMSDIST(-(((LN($B13/'Assumptions'!$B$5)+('Assumptions'!$B$9+0.5*'Assumptions'!$B$8^2)*(E$24/365))/('Assumptions'!$B$8*SQRT((E$24/365))))-'Assumptions'!$B$8*SQRT((E$24/365))))-$B13*NORMSDIST(-((LN($B13/'Assumptions'!$B$5)+('Assumptions'!$B$9+0.5*'Assumptions'!$B$8^2)*(E$24/365))/('Assumptions'!$B$8*SQRT((E$24/365)))))) | F13: =IF(F$24=0,MAX('Assumptions'!$B$5-$B13,0),'Assumptions'!$B$5*EXP(-'Assumptions'!$B$9*(F$24/365))*NORMSDIST(-(((LN($B13/'Assumptions'!$B$5)+('Assumptions'!$B$9+0.5*'Assumptions'!$B$8^2)*(F$24/365))/('Assumptions'!$B$8*SQRT((F$24/365))))-'Assumptions'!$B$8*SQRT((F$24/365))))-$B13*NORMSDIST(-((LN($B13/'Assumptions'!$B$5)+('Assumptions'!$B$9+0.5*'Assumptions'!$B$8^2)*(F$24/365))/('Assumptions'!$B$8*SQRT((F$24/365)))))) | G13: =IF(G$24=0,MAX('Assumptions'!$B$5-$B13,0),'Assumptions'!$B$5*EXP(-'Assumptions'!$B$9*(G$24/365))*NORMSDIST(-(((LN($B13/'Assumptions'!$B$5)+('Assumptions'!$B$9+0.5*'Assumptions'!$B$8^2)*(G$24/365))/('Assumptions'!$B$8*SQRT((G$24/365))))-'Assumptions'!$B$8*SQRT((G$24/365))))-$B13*NORMSDIST(-((LN($B13/'Assumptions'!$B$5)+('Assumptions'!$B$9+0.5*'Assumptions'!$B$8^2)*(G$24/365))/('Assumptions'!$B$8*SQRT((G$24/365)))))) | H13: =IF(H$24=0,MAX('Assumptions'!$B$5-$B13,0),'Assumptions'!$B$5*EXP(-'Assumptions'!$B$9*(H$24/365))*NORMSDIST(-(((LN($B13/'Assumptions'!$B$5)+('Assumptions'!$B$9+0.5*'Assumptions'!$B$8^2)*(H$24/365))/('Assumptions'!$B$8*SQRT((H$24/365))))-'Assumptions'!$B$8*SQRT((H$24/365))))-$B13*NORMSDIST(-((LN($B13/'Assumptions'!$B$5)+('Assumptions'!$B$9+0.5*'Assumptions'!$B$8^2)*(H$24/365))/('Assumptions'!$B$8*SQRT((H$24/365)))))) | I13: =IF(I$24=0,MAX('Assumptions'!$B$5-$B13,0),'Assumptions'!$B$5*EXP(-'Assumptions'!$B$9*(I$24/365))*NORMSDIST(-(((LN($B13/'Assumptions'!$B$5)+('Assumptions'!$B$9+0.5*'Assumptions'!$B$8^2)*(I$24/365))/('Assumptions'!$B$8*SQRT((I$24/365))))-'Assumptions'!$B$8*SQRT((I$24/365))))-$B13*NORMSDIST(-((LN($B13/'Assumptions'!$B$5)+('Assumptions'!$B$9+0.5*'Assumptions'!$B$8^2)*(I$24/365))/('Assumptions'!$B$8*SQRT((I$24/365)))))) | J13: =IF(J$24=0,MAX('Assumptions'!$B$5-$B13,0),'Assumptions'!$B$5*EXP(-'Assumptions'!$B$9*(J$24/365))*NORMSDIST(-(((LN($B13/'Assumptions'!$B$5)+('Assumptions'!$B$9+0.5*'Assumptions'!$B$8^2)*(J$24/365))/('Assumptions'!$B$8*SQRT((J$24/365))))-'Assumptions'!$B$8*SQRT((J$24/365))))-$B13*NORMSDIST(-((LN($B13/'Assumptions'!$B$5)+('Assumptions'!$B$9+0.5*'Assumptions'!$B$8^2)*(J$24/365))/('Assumptions'!$B$8*SQRT((J$24/365)))))) | ... U13: =IF(U$24=0,MAX('Assumptions'!$B$5-$B13,0),'Assumptions'!$B$5*EXP(-'Assumptions'!$B$9*(U$24/365))*NORMSDIST(-(((LN($B13/'Assumptions'!$B$5)+('Assumptions'!$B$9+0.5*'Assumptions'!$B$8^2)*(U$24/365))/('Assumptions'!$B$8*SQRT((U$24/365))))-'Assumptions'!$B$8*SQRT((U$24/365))))-$B13*NORMSDIST(-((LN($B13/'Assumptions'!$B$5)+('Assumptions'!$B$9+0.5*'Assumptions'!$B$8^2)*(U$24/365))/('Assumptions'!$B$8*SQRT((U$24/365))))))
A16: Important
A17: Scenario estimates only. Actual option prices may differ due to IV changes, early-exercise value, bid/ask spreads, and intraday market conditions.
C24: 18 | D24: 17 | E24: 16 | F24: 15 | G24: 14 | H24: 13 | I24: 12 | J24: 11 | K24: 10 | L24: 9 | M24: 8 | N24: 7 | O24: 6 | P24: 5 | Q24: 4 | R24: 3 | S24: 2 | T24: 1 | U24: 0

Sheet P&L Matrix
A1: P&L Matrix
A2: Rows = SPY decline from baseline. Columns = calendar days remaining until Aug. 28 expiration.
A3: SPY Drop | B3: SPY Price | C3: 18D | D3: 17D | E3: 16D | F3: 15D | G3: 14D | H3: 13D | I3: 12D | J3: 11D | K3: 10D | L3: 9D | M3: 8D | N3: 7D | O3: 6D | P3: 5D | Q3: 4D | R3: 3D | S3: 2D | T3: 1D | U3: 0D
A4: 0.01 | B4: ='Assumptions'!$B$4*(1-A4) | C4: =('Option Price Matrix'!C4-'Assumptions'!$B$6)*'Assumptions'!$B$7 | D4: =('Option Price Matrix'!D4-'Assumptions'!$B$6)*'Assumptions'!$B$7 | E4: =('Option Price Matrix'!E4-'Assumptions'!$B$6)*'Assumptions'!$B$7 | F4: =('Option Price Matrix'!F4-'Assumptions'!$B$6)*'Assumptions'!$B$7 | G4: =('Option Price Matrix'!G4-'Assumptions'!$B$6)*'Assumptions'!$B$7 | H4: =('Option Price Matrix'!H4-'Assumptions'!$B$6)*'Assumptions'!$B$7 | I4: =('Option Price Matrix'!I4-'Assumptions'!$B$6)*'Assumptions'!$B$7 | J4: =('Option Price Matrix'!J4-'Assumptions'!$B$6)*'Assumptions'!$B$7 | ... U4: =('Option Price Matrix'!U4-'Assumptions'!$B$6)*'Assumptions'!$B$7
A5: 0.02 | B5: ='Assumptions'!$B$4*(1-A5) | C5: =('Option Price Matrix'!C5-'Assumptions'!$B$6)*'Assumptions'!$B$7 | D5: =('Option Price Matrix'!D5-'Assumptions'!$B$6)*'Assumptions'!$B$7 | E5: =('Option Price Matrix'!E5-'Assumptions'!$B$6)*'Assumptions'!$B$7 | F5: =('Option Price Matrix'!F5-'Assumptions'!$B$6)*'Assumptions'!$B$7 | G5: =('Option Price Matrix'!G5-'Assumptions'!$B$6)*'Assumptions'!$B$7 | H5: =('Option Price Matrix'!H5-'Assumptions'!$B$6)*'Assumptions'!$B$7 | I5: =('Option Price Matrix'!I5-'Assumptions'!$B$6)*'Assumptions'!$B$7 | J5: =('Option Price Matrix'!J5-'Assumptions'!$B$6)*'Assumptions'!$B$7 | ... U5: =('Option Price Matrix'!U5-'Assumptions'!$B$6)*'Assumptions'!$B$7
A6: 0.03 | B6: ='Assumptions'!$B$4*(1-A6) | C6: =('Option Price Matrix'!C6-'Assumptions'!$B$6)*'Assumptions'!$B$7 | D6: =('Option Price Matrix'!D6-'Assumptions'!$B$6)*'Assumptions'!$B$7 | E6: =('Option Price Matrix'!E6-'Assumptions'!$B$6)*'Assumptions'!$B$7 | F6: =('Option Price Matrix'!F6-'Assumptions'!$B$6)*'Assumptions'!$B$7 | G6: =('Option Price Matrix'!G6-'Assumptions'!$B$6)*'Assumptions'!$B$7 | H6: =('Option Price Matrix'!H6-'Assumptions'!$B$6)*'Assumptions'!$B$7 | I6: =('Option Price Matrix'!I6-'Assumptions'!$B$6)*'Assumptions'!$B$7 | J6: =('Option Price Matrix'!J6-'Assumptions'!$B$6)*'Assumptions'!$B$7 | ... U6: =('Option Price Matrix'!U6-'Assumptions'!$B$6)*'Assumptions'!$B$7
A7: 0.04 | B7: ='Assumptions'!$B$4*(1-A7) | C7: =('Option Price Matrix'!C7-'Assumptions'!$B$6)*'Assumptions'!$B$7 | D7: =('Option Price Matrix'!D7-'Assumptions'!$B$6)*'Assumptions'!$B$7 | E7: =('Option Price Matrix'!E7-'Assumptions'!$B$6)*'Assumptions'!$B$7 | F7: =('Option Price Matrix'!F7-'Assumptions'!$B$6)*'Assumptions'!$B$7 | G7: =('Option Price Matrix'!G7-'Assumptions'!$B$6)*'Assumptions'!$B$7 | H7: =('Option Price Matrix'!H7-'Assumptions'!$B$6)*'Assumptions'!$B$7 | I7: =('Option Price Matrix'!I7-'Assumptions'!$B$6)*'Assumptions'!$B$7 | J7: =('Option Price Matrix'!J7-'Assumptions'!$B$6)*'Assumptions'!$B$7 | ... U7: =('Option Price Matrix'!U7-'Assumptions'!$B$6)*'Assumptions'!$B$7
A8: 0.05 | B8: ='Assumptions'!$B$4*(1-A8) | C8: =('Option Price Matrix'!C8-'Assumptions'!$B$6)*'Assumptions'!$B$7 | D8: =('Option Price Matrix'!D8-'Assumptions'!$B$6)*'Assumptions'!$B$7 | E8: =('Option Price Matrix'!E8-'Assumptions'!$B$6)*'Assumptions'!$B$7 | F8: =('Option Price Matrix'!F8-'Assumptions'!$B$6)*'Assumptions'!$B$7 | G8: =('Option Price Matrix'!G8-'Assumptions'!$B$6)*'Assumptions'!$B$7 | H8: =('Option Price Matrix'!H8-'Assumptions'!$B$6)*'Assumptions'!$B$7 | I8: =('Option Price Matrix'!I8-'Assumptions'!$B$6)*'Assumptions'!$B$7 | J8: =('Option Price Matrix'!J8-'Assumptions'!$B$6)*'Assumptions'!$B$7 | ... U8: =('Option Price Matrix'!U8-'Assumptions'!$B$6)*'Assumptions'!$B$7
A9: 0.06 | B9: ='Assumptions'!$B$4*(1-A9) | C9: =('Option Price Matrix'!C9-'Assumptions'!$B$6)*'Assumptions'!$B$7 | D9: =('Option Price Matrix'!D9-'Assumptions'!$B$6)*'Assumptions'!$B$7 | E9: =('Option Price Matrix'!E9-'Assumptions'!$B$6)*'Assumptions'!$B$7 | F9: =('Option Price Matrix'!F9-'Assumptions'!$B$6)*'Assumptions'!$B$7 | G9: =('Option Price Matrix'!G9-'Assumptions'!$B$6)*'Assumptions'!$B$7 | H9: =('Option Price Matrix'!H9-'Assumptions'!$B$6)*'Assumptions'!$B$7 | I9: =('Option Price Matrix'!I9-'Assumptions'!$B$6)*'Assumptions'!$B$7 | J9: =('Option Price Matrix'!J9-'Assumptions'!$B$6)*'Assumptions'!$B$7 | ... U9: =('Option Price Matrix'!U9-'Assumptions'!$B$6)*'Assumptions'!$B$7
A10: 0.07 | B10: ='Assumptions'!$B$4*(1-A10) | C10: =('Option Price Matrix'!C10-'Assumptions'!$B$6)*'Assumptions'!$B$7 | D10: =('Option Price Matrix'!D10-'Assumptions'!$B$6)*'Assumptions'!$B$7 | E10: =('Option Price Matrix'!E10-'Assumptions'!$B$6)*'Assumptions'!$B$7 | F10: =('Option Price Matrix'!F10-'Assumptions'!$B$6)*'Assumptions'!$B$7 | G10: =('Option Price Matrix'!G10-'Assumptions'!$B$6)*'Assumptions'!$B$7 | H10: =('Option Price Matrix'!H10-'Assumptions'!$B$6)*'Assumptions'!$B$7 | I10: =('Option Price Matrix'!I10-'Assumptions'!$B$6)*'Assumptions'!$B$7 | J10: =('Option Price Matrix'!J10-'Assumptions'!$B$6)*'Assumptions'!$B$7 | ... U10: =('Option Price Matrix'!U10-'Assumptions'!$B$6)*'Assumptions'!$B$7
A11: 0.08 | B11: ='Assumptions'!$B$4*(1-A11) | C11: =('Option Price Matrix'!C11-'Assumptions'!$B$6)*'Assumptions'!$B$7 | D11: =('Option Price Matrix'!D11-'Assumptions'!$B$6)*'Assumptions'!$B$7 | E11: =('Option Price Matrix'!E11-'Assumptions'!$B$6)*'Assumptions'!$B$7 | F11: =('Option Price Matrix'!F11-'Assumptions'!$B$6)*'Assumptions'!$B$7 | G11: =('Option Price Matrix'!G11-'Assumptions'!$B$6)*'Assumptions'!$B$7 | H11: =('Option Price Matrix'!H11-'Assumptions'!$B$6)*'Assumptions'!$B$7 | I11: =('Option Price Matrix'!I11-'Assumptions'!$B$6)*'Assumptions'!$B$7 | J11: =('Option Price Matrix'!J11-'Assumptions'!$B$6)*'Assumptions'!$B$7 | ... U11: =('Option Price Matrix'!U11-'Assumptions'!$B$6)*'Assumptions'!$B$7
A12: 0.09 | B12: ='Assumptions'!$B$4*(1-A12) | C12: =('Option Price Matrix'!C12-'Assumptions'!$B$6)*'Assumptions'!$B$7 | D12: =('Option Price Matrix'!D12-'Assumptions'!$B$6)*'Assumptions'!$B$7 | E12: =('Option Price Matrix'!E12-'Assumptions'!$B$6)*'Assumptions'!$B$7 | F12: =('Option Price Matrix'!F12-'Assumptions'!$B$6)*'Assumptions'!$B$7 | G12: =('Option Price Matrix'!G12-'Assumptions'!$B$6)*'Assumptions'!$B$7 | H12: =('Option Price Matrix'!H12-'Assumptions'!$B$6)*'Assumptions'!$B$7 | I12: =('Option Price Matrix'!I12-'Assumptions'!$B$6)*'Assumptions'!$B$7 | J12: =('Option Price Matrix'!J12-'Assumptions'!$B$6)*'Assumptions'!$B$7 | ... U12: =('Option Price Matrix'!U12-'Assumptions'!$B$6)*'Assumptions'!$B$7
A13: 0.1 | B13: ='Assumptions'!$B$4*(1-A13) | C13: =('Option Price Matrix'!C13-'Assumptions'!$B$6)*'Assumptions'!$B$7 | D13: =('Option Price Matrix'!D13-'Assumptions'!$B$6)*'Assumptions'!$B$7 | E13: =('Option Price Matrix'!E13-'Assumptions'!$B$6)*'Assumptions'!$B$7 | F13: =('Option Price Matrix'!F13-'Assumptions'!$B$6)*'Assumptions'!$B$7 | G13: =('Option Price Matrix'!G13-'Assumptions'!$B$6)*'Assumptions'!$B$7 | H13: =('Option Price Matrix'!H13-'Assumptions'!$B$6)*'Assumptions'!$B$7 | I13: =('Option Price Matrix'!I13-'Assumptions'!$B$6)*'Assumptions'!$B$7 | J13: =('Option Price Matrix'!J13-'Assumptions'!$B$6)*'Assumptions'!$B$7 | ... U13: =('Option Price Matrix'!U13-'Assumptions'!$B$6)*'Assumptions'!$B$7
A16: Important
A17: Scenario estimates only. Actual option prices may differ due to IV changes, early-exercise value, bid/ask spreads, and intraday market conditions.
C24: 18 | D24: 17 | E24: 16 | F24: 15 | G24: 14 | H24: 13 | I24: 12 | J24: 11 | K24: 10 | L24: 9 | M24: 8 | N24: 7 | O24: 6 | P24: 5 | Q24: 4 | R24: 3 | S24: 2 | T24: 1 | U24: 0

Sheet Combined View
A1: Combined View
A2: Each cell = estimated option price / contract P&L. Example: $5.98 / +$388.
A3: SPY Drop | B3: SPY Price | C3: 18D | D3: 17D | E3: 16D | F3: 15D | G3: 14D | H3: 13D | I3: 12D | J3: 11D | K3: 10D | L3: 9D | M3: 8D | N3: 7D | O3: 6D | P3: 5D | Q3: 4D | R3: 3D | S3: 2D | T3: 1D | U3: 0D
A4: 0.01 | B4: ='Assumptions'!$B$4*(1-A4) | C4: =TEXT('Option Price Matrix'!C4,"$0.00")&" / "&IF('P&L Matrix'!C4>0,"+$"&TEXT('P&L Matrix'!C4,"#,##0"),IF('P&L Matrix'!C4<0,"-$"&TEXT(ABS('P&L Matrix'!C4),"#,##0"),"$0")) | D4: =TEXT('Option Price Matrix'!D4,"$0.00")&" / "&IF('P&L Matrix'!D4>0,"+$"&TEXT('P&L Matrix'!D4,"#,##0"),IF('P&L Matrix'!D4<0,"-$"&TEXT(ABS('P&L Matrix'!D4),"#,##0"),"$0")) | E4: =TEXT('Option Price Matrix'!E4,"$0.00")&" / "&IF('P&L Matrix'!E4>0,"+$"&TEXT('P&L Matrix'!E4,"#,##0"),IF('P&L Matrix'!E4<0,"-$"&TEXT(ABS('P&L Matrix'!E4),"#,##0"),"$0")) | F4: =TEXT('Option Price Matrix'!F4,"$0.00")&" / "&IF('P&L Matrix'!F4>0,"+$"&TEXT('P&L Matrix'!F4,"#,##0"),IF('P&L Matrix'!F4<0,"-$"&TEXT(ABS('P&L Matrix'!F4),"#,##0"),"$0")) | G4: =TEXT('Option Price Matrix'!G4,"$0.00")&" / "&IF('P&L Matrix'!G4>0,"+$"&TEXT('P&L Matrix'!G4,"#,##0"),IF('P&L Matrix'!G4<0,"-$"&TEXT(ABS('P&L Matrix'!G4),"#,##0"),"$0")) | H4: =TEXT('Option Price Matrix'!H4,"$0.00")&" / "&IF('P&L Matrix'!H4>0,"+$"&TEXT('P&L Matrix'!H4,"#,##0"),IF('P&L Matrix'!H4<0,"-$"&TEXT(ABS('P&L Matrix'!H4),"#,##0"),"$0")) | I4: =TEXT('Option Price Matrix'!I4,"$0.00")&" / "&IF('P&L Matrix'!I4>0,"+$"&TEXT('P&L Matrix'!I4,"#,##0"),IF('P&L Matrix'!I4<0,"-$"&TEXT(ABS('P&L Matrix'!I4),"#,##0"),"$0")) | J4: =TEXT('Option Price Matrix'!J4,"$0.00")&" / "&IF('P&L Matrix'!J4>0,"+$"&TEXT('P&L Matrix'!J4,"#,##0"),IF('P&L Matrix'!J4<0,"-$"&TEXT(ABS('P&L Matrix'!J4),"#,##0"),"$0")) | ... U4: =TEXT('Option Price Matrix'!U4,"$0.00")&" / "&IF('P&L Matrix'!U4>0,"+$"&TEXT('P&L Matrix'!U4,"#,##0"),IF('P&L Matrix'!U4<0,"-$"&TEXT(ABS('P&L Matrix'!U4),"#,##0"),"$0"))
A5: 0.02 | B5: ='Assumptions'!$B$4*(1-A5) | C5: =TEXT('Option Price Matrix'!C5,"$0.00")&" / "&IF('P&L Matrix'!C5>0,"+$"&TEXT('P&L Matrix'!C5,"#,##0"),IF('P&L Matrix'!C5<0,"-$"&TEXT(ABS('P&L Matrix'!C5),"#,##0"),"$0")) | D5: =TEXT('Option Price Matrix'!D5,"$0.00")&" / "&IF('P&L Matrix'!D5>0,"+$"&TEXT('P&L Matrix'!D5,"#,##0"),IF('P&L Matrix'!D5<0,"-$"&TEXT(ABS('P&L Matrix'!D5),"#,##0"),"$0")) | E5: =TEXT('Option Price Matrix'!E5,"$0.00")&" / "&IF('P&L Matrix'!E5>0,"+$"&TEXT('P&L Matrix'!E5,"#,##0"),IF('P&L Matrix'!E5<0,"-$"&TEXT(ABS('P&L Matrix'!E5),"#,##0"),"$0")) | F5: =TEXT('Option Price Matrix'!F5,"$0.00")&" / "&IF('P&L Matrix'!F5>0,"+$"&TEXT('P&L Matrix'!F5,"#,##0"),IF('P&L Matrix'!F5<0,"-$"&TEXT(ABS('P&L Matrix'!F5),"#,##0"),"$0")) | G5: =TEXT('Option Price Matrix'!G5,"$0.00")&" / "&IF('P&L Matrix'!G5>0,"+$"&TEXT('P&L Matrix'!G5,"#,##0"),IF('P&L Matrix'!G5<0,"-$"&TEXT(ABS('P&L Matrix'!G5),"#,##0"),"$0")) | H5: =TEXT('Option Price Matrix'!H5,"$0.00")&" / "&IF('P&L Matrix'!H5>0,"+$"&TEXT('P&L Matrix'!H5,"#,##0"),IF('P&L Matrix'!H5<0,"-$"&TEXT(ABS('P&L Matrix'!H5),"#,##0"),"$0")) | I5: =TEXT('Option Price Matrix'!I5,"$0.00")&" / "&IF('P&L Matrix'!I5>0,"+$"&TEXT('P&L Matrix'!I5,"#,##0"),IF('P&L Matrix'!I5<0,"-$"&TEXT(ABS('P&L Matrix'!I5),"#,##0"),"$0")) | J5: =TEXT('Option Price Matrix'!J5,"$0.00")&" / "&IF('P&L Matrix'!J5>0,"+$"&TEXT('P&L Matrix'!J5,"#,##0"),IF('P&L Matrix'!J5<0,"-$"&TEXT(ABS('P&L Matrix'!J5),"#,##0"),"$0")) | ... U5: =TEXT('Option Price Matrix'!U5,"$0.00")&" / "&IF('P&L Matrix'!U5>0,"+$"&TEXT('P&L Matrix'!U5,"#,##0"),IF('P&L Matrix'!U5<0,"-$"&TEXT(ABS('P&L Matrix'!U5),"#,##0"),"$0"))
A6: 0.03 | B6: ='Assumptions'!$B$4*(1-A6) | C6: =TEXT('Option Price Matrix'!C6,"$0.00")&" / "&IF('P&L Matrix'!C6>0,"+$"&TEXT('P&L Matrix'!C6,"#,##0"),IF('P&L Matrix'!C6<0,"-$"&TEXT(ABS('P&L Matrix'!C6),"#,##0"),"$0")) | D6: =TEXT('Option Price Matrix'!D6,"$0.00")&" / "&IF('P&L Matrix'!D6>0,"+$"&TEXT('P&L Matrix'!D6,"#,##0"),IF('P&L Matrix'!D6<0,"-$"&TEXT(ABS('P&L Matrix'!D6),"#,##0"),"$0")) | E6: =TEXT('Option Price Matrix'!E6,"$0.00")&" / "&IF('P&L Matrix'!E6>0,"+$"&TEXT('P&L Matrix'!E6,"#,##0"),IF('P&L Matrix'!E6<0,"-$"&TEXT(ABS('P&L Matrix'!E6),"#,##0"),"$0")) | F6: =TEXT('Option Price Matrix'!F6,"$0.00")&" / "&IF('P&L Matrix'!F6>0,"+$"&TEXT('P&L Matrix'!F6,"#,##0"),IF('P&L Matrix'!F6<0,"-$"&TEXT(ABS('P&L Matrix'!F6),"#,##0"),"$0")) | G6: =TEXT('Option Price Matrix'!G6,"$0.00")&" / "&IF('P&L Matrix'!G6>0,"+$"&TEXT('P&L Matrix'!G6,"#,##0"),IF('P&L Matrix'!G6<0,"-$"&TEXT(ABS('P&L Matrix'!G6),"#,##0"),"$0")) | H6: =TEXT('Option Price Matrix'!H6,"$0.00")&" / "&IF('P&L Matrix'!H6>0,"+$"&TEXT('P&L Matrix'!H6,"#,##0"),IF('P&L Matrix'!H6<0,"-$"&TEXT(ABS('P&L Matrix'!H6),"#,##0"),"$0")) | I6: =TEXT('Option Price Matrix'!I6,"$0.00")&" / "&IF('P&L Matrix'!I6>0,"+$"&TEXT('P&L Matrix'!I6,"#,##0"),IF('P&L Matrix'!I6<0,"-$"&TEXT(ABS('P&L Matrix'!I6),"#,##0"),"$0")) | J6: =TEXT('Option Price Matrix'!J6,"$0.00")&" / "&IF('P&L Matrix'!J6>0,"+$"&TEXT('P&L Matrix'!J6,"#,##0"),IF('P&L Matrix'!J6<0,"-$"&TEXT(ABS('P&L Matrix'!J6),"#,##0"),"$0")) | ... U6: =TEXT('Option Price Matrix'!U6,"$0.00")&" / "&IF('P&L Matrix'!U6>0,"+$"&TEXT('P&L Matrix'!U6,"#,##0"),IF('P&L Matrix'!U6<0,"-$"&TEXT(ABS('P&L Matrix'!U6),"#,##0"),"$0"))
A7: 0.04 | B7: ='Assumptions'!$B$4*(1-A7) | C7: =TEXT('Option Price Matrix'!C7,"$0.00")&" / "&IF('P&L Matrix'!C7>0,"+$"&TEXT('P&L Matrix'!C7,"#,##0"),IF('P&L Matrix'!C7<0,"-$"&TEXT(ABS('P&L Matrix'!C7),"#,##0"),"$0")) | D7: =TEXT('Option Price Matrix'!D7,"$0.00")&" / "&IF('P&L Matrix'!D7>0,"+$"&TEXT('P&L Matrix'!D7,"#,##0"),IF('P&L Matrix'!D7<0,"-$"&TEXT(ABS('P&L Matrix'!D7),"#,##0"),"$0")) | E7: =TEXT('Option Price Matrix'!E7,"$0.00")&" / "&IF('P&L Matrix'!E7>0,"+$"&TEXT('P&L Matrix'!E7,"#,##0"),IF('P&L Matrix'!E7<0,"-$"&TEXT(ABS('P&L Matrix'!E7),"#,##0"),"$0")) | F7: =TEXT('Option Price Matrix'!F7,"$0.00")&" / "&IF('P&L Matrix'!F7>0,"+$"&TEXT('P&L Matrix'!F7,"#,##0"),IF('P&L Matrix'!F7<0,"-$"&TEXT(ABS('P&L Matrix'!F7),"#,##0"),"$0")) | G7: =TEXT('Option Price Matrix'!G7,"$0.00")&" / "&IF('P&L Matrix'!G7>0,"+$"&TEXT('P&L Matrix'!G7,"#,##0"),IF('P&L Matrix'!G7<0,"-$"&TEXT(ABS('P&L Matrix'!G7),"#,##0"),"$0")) | H7: =TEXT('Option Price Matrix'!H7,"$0.00")&" / "&IF('P&L Matrix'!H7>0,"+$"&TEXT('P&L Matrix'!H7,"#,##0"),IF('P&L Matrix'!H7<0,"-$"&TEXT(ABS('P&L Matrix'!H7),"#,##0"),"$0")) | I7: =TEXT('Option Price Matrix'!I7,"$0.00")&" / "&IF('P&L Matrix'!I7>0,"+$"&TEXT('P&L Matrix'!I7,"#,##0"),IF('P&L Matrix'!I7<0,"-$"&TEXT(ABS('P&L Matrix'!I7),"#,##0"),"$0")) | J7: =TEXT('Option Price Matrix'!J7,"$0.00")&" / "&IF('P&L Matrix'!J7>0,"+$"&TEXT('P&L Matrix'!J7,"#,##0"),IF('P&L Matrix'!J7<0,"-$"&TEXT(ABS('P&L Matrix'!J7),"#,##0"),"$0")) | ... U7: =TEXT('Option Price Matrix'!U7,"$0.00")&" / "&IF('P&L Matrix'!U7>0,"+$"&TEXT('P&L Matrix'!U7,"#,##0"),IF('P&L Matrix'!U7<0,"-$"&TEXT(ABS('P&L Matrix'!U7),"#,##0"),"$0"))
A8: 0.05 | B8: ='Assumptions'!$B$4*(1-A8) | C8: =TEXT('Option Price Matrix'!C8,"$0.00")&" / "&IF('P&L Matrix'!C8>0,"+$"&TEXT('P&L Matrix'!C8,"#,##0"),IF('P&L Matrix'!C8<0,"-$"&TEXT(ABS('P&L Matrix'!C8),"#,##0"),"$0")) | D8: =TEXT('Option Price Matrix'!D8,"$0.00")&" / "&IF('P&L Matrix'!D8>0,"+$"&TEXT('P&L Matrix'!D8,"#,##0"),IF('P&L Matrix'!D8<0,"-$"&TEXT(ABS('P&L Matrix'!D8),"#,##0"),"$0")) | E8: =TEXT('Option Price Matrix'!E8,"$0.00")&" / "&IF('P&L Matrix'!E8>0,"+$"&TEXT('P&L Matrix'!E8,"#,##0"),IF('P&L Matrix'!E8<0,"-$"&TEXT(ABS('P&L Matrix'!E8),"#,##0"),"$0")) | F8: =TEXT('Option Price Matrix'!F8,"$0.00")&" / "&IF('P&L Matrix'!F8>0,"+$"&TEXT('P&L Matrix'!F8,"#,##0"),IF('P&L Matrix'!F8<0,"-$"&TEXT(ABS('P&L Matrix'!F8),"#,##0"),"$0")) | G8: =TEXT('Option Price Matrix'!G8,"$0.00")&" / "&IF('P&L Matrix'!G8>0,"+$"&TEXT('P&L Matrix'!G8,"#,##0"),IF('P&L Matrix'!G8<0,"-$"&TEXT(ABS('P&L Matrix'!G8),"#,##0"),"$0")) | H8: =TEXT('Option Price Matrix'!H8,"$0.00")&" / "&IF('P&L Matrix'!H8>0,"+$"&TEXT('P&L Matrix'!H8,"#,##0"),IF('P&L Matrix'!H8<0,"-$"&TEXT(ABS('P&L Matrix'!H8),"#,##0"),"$0")) | I8: =TEXT('Option Price Matrix'!I8,"$0.00")&" / "&IF('P&L Matrix'!I8>0,"+$"&TEXT('P&L Matrix'!I8,"#,##0"),IF('P&L Matrix'!I8<0,"-$"&TEXT(ABS('P&L Matrix'!I8),"#,##0"),"$0")) | J8: =TEXT('Option Price Matrix'!J8,"$0.00")&" / "&IF('P&L Matrix'!J8>0,"+$"&TEXT('P&L Matrix'!J8,"#,##0"),IF('P&L Matrix'!J8<0,"-$"&TEXT(ABS('P&L Matrix'!J8),"#,##0"),"$0")) | ... U8: =TEXT('Option Price Matrix'!U8,"$0.00")&" / "&IF('P&L Matrix'!U8>0,"+$"&TEXT('P&L Matrix'!U8,"#,##0"),IF('P&L Matrix'!U8<0,"-$"&TEXT(ABS('P&L Matrix'!U8),"#,##0"),"$0"))
A9: 0.06 | B9: ='Assumptions'!$B$4*(1-A9) | C9: =TEXT('Option Price Matrix'!C9,"$0.00")&" / "&IF('P&L Matrix'!C9>0,"+$"&TEXT('P&L Matrix'!C9,"#,##0"),IF('P&L Matrix'!C9<0,"-$"&TEXT(ABS('P&L Matrix'!C9),"#,##0"),"$0")) | D9: =TEXT('Option Price Matrix'!D9,"$0.00")&" / "&IF('P&L Matrix'!D9>0,"+$"&TEXT('P&L Matrix'!D9,"#,##0"),IF('P&L Matrix'!D9<0,"-$"&TEXT(ABS('P&L Matrix'!D9),"#,##0"),"$0")) | E9: =TEXT('Option Price Matrix'!E9,"$0.00")&" / "&IF('P&L Matrix'!E9>0,"+$"&TEXT('P&L Matrix'!E9,"#,##0"),IF('P&L Matrix'!E9<0,"-$"&TEXT(ABS('P&L Matrix'!E9),"#,##0"),"$0")) | F9: =TEXT('Option Price Matrix'!F9,"$0.00")&" / "&IF('P&L Matrix'!F9>0,"+$"&TEXT('P&L Matrix'!F9,"#,##0"),IF('P&L Matrix'!F9<0,"-$"&TEXT(ABS('P&L Matrix'!F9),"#,##0"),"$0")) | G9: =TEXT('Option Price Matrix'!G9,"$0.00")&" / "&IF('P&L Matrix'!G9>0,"+$"&TEXT('P&L Matrix'!G9,"#,##0"),IF('P&L Matrix'!G9<0,"-$"&TEXT(ABS('P&L Matrix'!G9),"#,##0"),"$0")) | H9: =TEXT('Option Price Matrix'!H9,"$0.00")&" / "&IF('P&L Matrix'!H9>0,"+$"&TEXT('P&L Matrix'!H9,"#,##0"),IF('P&L Matrix'!H9<0,"-$"&TEXT(ABS('P&L Matrix'!H9),"#,##0"),"$0")) | I9: =TEXT('Option Price Matrix'!I9,"$0.00")&" / "&IF('P&L Matrix'!I9>0,"+$"&TEXT('P&L Matrix'!I9,"#,##0"),IF('P&L Matrix'!I9<0,"-$"&TEXT(ABS('P&L Matrix'!I9),"#,##0"),"$0")) | J9: =TEXT('Option Price Matrix'!J9,"$0.00")&" / "&IF('P&L Matrix'!J9>0,"+$"&TEXT('P&L Matrix'!J9,"#,##0"),IF('P&L Matrix'!J9<0,"-$"&TEXT(ABS('P&L Matrix'!J9),"#,##0"),"$0")) | ... U9: =TEXT('Option Price Matrix'!U9,"$0.00")&" / "&IF('P&L Matrix'!U9>0,"+$"&TEXT('P&L Matrix'!U9,"#,##0"),IF('P&L Matrix'!U9<0,"-$"&TEXT(ABS('P&L Matrix'!U9),"#,##0"),"$0"))
